<?xml version="1.0" encoding="UTF-8"?>
<robot name="Robot">
    <link name="Base">
        <inertial>
            <mass value="0"/>
            <inertia ixx="0" ixy="0" ixz="0" iyy="0" iyz="0" izz="0"/>
        </inertial>
    </link>
    <link name="Body01">
        <inertial>
            <origin rpy="0.00000000 0.00000000 0.00000000" xyz="0.00000000  0.00000000 -0.07952202"/>
            <mass value="4.11698047"/>
            <inertia ixx="0.11355786" ixy="0.00000000" ixz="0.00000000" iyy="0.10863918" iyz="0.00000000" izz="0.00566368"/>
        </inertial>
    </link>
    <link name="Body02">
        <inertial>
            <origin rpy="0.00000000 0.00000000 0.00000000" xyz="0.00000365 -0.00000317  0.00021471"/>
            <mass value="55.97256511"/>
            <inertia ixx="1.09333456" ixy="0.00001735" ixz="0.00000000" iyy="1.09333949" iyz="0.00000000" izz="1.19125399"/>
        </inertial>
    </link>
    <link name="Body03">
        <inertial>
            <origin rpy="0.00000000 0.00000000 0.00000000" xyz="0.00000365 -0.00000317  0.00021471"/>
            <mass value="55.97256511"/>
            <inertia ixx="1.09333456" ixy="0.00001735" ixz="0.00000000" iyy="1.09333949" iyz="0.00000000" izz="1.19125399"/>
        </inertial>
    </link>
    <link name="Body04">
        <inertial>
            <origin rpy="0.00000000 0.00000000 0.00000000" xyz="-0.00246739  0.00000000  0.10000000"/>
            <mass value="5.68436938"/>
            <inertia ixx="0.02123452" ixy="0.00000000" ixz="0.00000000" iyy="0.02044047" iyz="0.00000000" izz="0.00523910"/>
        </inertial>
    </link>
    <link name="Body05">
        <inertial>
            <origin rpy="0.00000000 0.00000000 0.00000000" xyz="0.00000365 -0.00000317  0.00021471"/>
            <mass value="55.97256511"/>
            <inertia ixx="1.09333456" ixy="0.00001735" ixz="0.00000000" iyy="1.09333949" iyz="0.00000000" izz="1.19125399"/>
        </inertial>
    </link>
    <link name="Body06">
        <inertial>
            <origin rpy="0.00000000 0.00000000 0.00000000" xyz="0.00000365 -0.00000317  0.00021471"/>
            <mass value="55.97256511"/>
            <inertia ixx="1.09333456" ixy="0.00001735" ixz="0.00000000" iyy="1.09333949" iyz="0.00000000" izz="1.19125399"/>
        </inertial>
    </link>
    <link name="Body07">
        <inertial>
            <origin rpy="0.00000000 0.00000000 0.00000000" xyz="0.00000000  0.00000000 -0.07952202"/>
            <mass value="4.11698047"/>
            <inertia ixx="0.11355786" ixy="0.00000000" ixz="0.00000000" iyy="0.10863918" iyz="0.00000000" izz="0.00566368"/>
        </inertial>
    </link>
    <link name="Body08">
        <inertial>
            <origin rpy="0.00000000 0.00000000 0.00000000" xyz="0.00000365 -0.00000317  0.00021471"/>
            <mass value="55.97256511"/>
            <inertia ixx="1.09333456" ixy="0.00001735" ixz="0.00000000" iyy="1.09333949" iyz="0.00000000" izz="1.19125399"/>
        </inertial>
    </link>
    <link name="Body09">
        <inertial>
            <origin rpy="0.00000000 0.00000000 0.00000000" xyz="0.00000365 -0.00000317  0.00021471"/>
            <mass value="55.97256511"/>
            <inertia ixx="1.09333456" ixy="0.00001735" ixz="0.00000000" iyy="1.09333949" iyz="0.00000000" izz="1.19125399"/>
        </inertial>
    </link>
    <link name="Body10">
        <inertial>
            <origin rpy="0.00000000 0.00000000 0.00000000" xyz="-0.00246739  0.00000000  0.10000000"/>
            <mass value="5.68436938"/>
            <inertia ixx="0.02123452" ixy="0.00000000" ixz="0.00000000" iyy="0.02044047" iyz="0.00000000" izz="0.00523910"/>
        </inertial>
    </link>
    <link name="Body11">
        <inertial>
            <origin rpy="0.00000000 0.00000000 0.00000000" xyz="0.00000365 -0.00000317  0.00021471"/>
            <mass value="55.97256511"/>
            <inertia ixx="1.09333456" ixy="0.00001735" ixz="0.00000000" iyy="1.09333949" iyz="0.00000000" izz="1.19125399"/>
        </inertial>
    </link>
    <link name="Body12">
        <inertial>
            <origin rpy="0.00000000 0.00000000 0.00000000" xyz="0.00000365 -0.00000317  0.00021471"/>
            <mass value="55.97256511"/>
            <inertia ixx="1.09333456" ixy="0.00001735" ixz="0.00000000" iyy="1.09333949" iyz="0.00000000" izz="1.19125399"/>
        </inertial>
    </link>
    <joint name="Joint01" type="revolute">
        <parent link="Base"/>
        <child link="Body01"/>
        <origin rpy="0.00000000 0.00000000 0.00000000" xyz="0.78500000 1.05000000 0.52500000"/>
        <axis xyz="0.00000000 0.00000000 1.00000000"/>
        <limit lower="-3.14159265" upper="3.14159265" effort="0" velocity="0"/>
    </joint>
    <joint name="Joint02" type="revolute">
        <parent link="Body01"/>
        <child link="Body02"/>
        <origin rpy="-1.57079633  0.24248954  0.00000000" xyz="0.00000000 -0.11850000 -0.26800000"/>
        <axis xyz="0.00000000 0.00000000 1.00000000"/>
        <limit lower="-3.14159265" upper="3.14159265" effort="0" velocity="0"/>
    </joint>
    <joint name="Joint03" type="revolute">
        <parent link="Body01"/>
        <child link="Body03"/>
        <origin rpy="1.57079633 0.11763402 0.00000000" xyz="0.00000000  0.11850000 -0.26800000"/>
        <axis xyz="0.00000000 0.00000000 1.00000000"/>
        <limit lower="-3.14159265" upper="3.14159265" effort="0" velocity="0"/>
    </joint>
    <joint name="Joint04" type="revolute">
        <parent link="Base"/>
        <child link="Body04"/>
        <origin rpy="0.00000000 0.00000000 3.14159265" xyz="-0.78500000  1.05000000  0.52500000"/>
        <axis xyz="0.00000000 0.00000000 1.00000000"/>
        <limit lower="-3.14159265" upper="3.14159265" effort="0" velocity="0"/>
    </joint>
    <joint name="Joint05" type="revolute">
        <parent link="Body04"/>
        <child link="Body05"/>
        <origin rpy="1.57079633 0.11763402 0.00000000" xyz="-0.00000000  0.11850000 -0.26800000"/>
        <axis xyz="0.00000000 0.00000000 1.00000000"/>
        <limit lower="-3.14159265" upper="3.14159265" effort="0" velocity="0"/>
    </joint>
    <joint name="Joint06" type="revolute">
        <parent link="Body04"/>
        <child link="Body06"/>
        <origin rpy="-1.57079633  0.24248954  0.00000000" xyz="-0.00000000 -0.11850000 -0.26800000"/>
        <axis xyz="0.00000000 0.00000000 1.00000000"/>
        <limit lower="-3.14159265" upper="3.14159265" effort="0" velocity="0"/>
    </joint>
    <joint name="Joint07" type="revolute">
        <parent link="Base"/>
        <child link="Body07"/>
        <origin rpy="0.00000000 0.00000000 3.14159265" xyz="-0.78500000 -1.05000000  0.52500000"/>
        <axis xyz="0.00000000 0.00000000 1.00000000"/>
        <limit lower="-3.14159265" upper="3.14159265" effort="0" velocity="0"/>
    </joint>
    <joint name="Joint08" type="revolute">
        <parent link="Body07"/>
        <child link="Body08"/>
        <origin rpy="1.57079633 0.11763402 0.00000000" xyz="0.00000000  0.11850000 -0.26800000"/>
        <axis xyz="0.00000000 0.00000000 1.00000000"/>
        <limit lower="-3.14159265" upper="3.14159265" effort="0" velocity="0"/>
    </joint>
    <joint name="Joint09" type="revolute">
        <parent link="Body07"/>
        <child link="Body09"/>
        <origin rpy="-1.57079633  0.24248954  0.00000000" xyz="0.00000000 -0.11850000 -0.26800000"/>
        <axis xyz="0.00000000 0.00000000 1.00000000"/>
        <limit lower="-3.14159265" upper="3.14159265" effort="0" velocity="0"/>
    </joint>
    <joint name="Joint10" type="revolute">
        <parent link="Base"/>
        <child link="Body10"/>
        <origin rpy="0.00000000 0.00000000 0.00000000" xyz="0.78500000 -1.05000000  0.52500000"/>
        <axis xyz="0.00000000 0.00000000 1.00000000"/>
        <limit lower="-3.14159265" upper="3.14159265" effort="0" velocity="0"/>
    </joint>
    <joint name="Joint11" type="revolute">
        <parent link="Body10"/>
        <child link="Body11"/>
        <origin rpy="-1.57079633  0.24248954  0.00000000" xyz="-0.00000000 -0.11850000 -0.26800000"/>
        <axis xyz="0.00000000 0.00000000 1.00000000"/>
        <limit lower="-3.14159265" upper="3.14159265" effort="0" velocity="0"/>
    </joint>
    <joint name="Joint12" type="revolute">
        <parent link="Body10"/>
        <child link="Body12"/>
        <origin rpy="1.57079633 0.11763402 0.00000000" xyz="-0.00000000  0.11850000 -0.26800000"/>
        <axis xyz="0.00000000 0.00000000 1.00000000"/>
        <limit lower="-3.14159265" upper="3.14159265" effort="0" velocity="0"/>
    </joint>
</robot>
