<?xml version="1.0" ?>

    <sdf version="1.9">

        <world name="agro_world">
            <spherical_coordinates>
                <surface_model>EARTH_WGS84</surface_model>
                <world_frame_orientation>ENU</world_frame_orientation>
                <latitude_deg>-22.</latitude_deg>
                <longitude_deg>-43.</longitude_deg>
                <elevation>0</elevation>
                <heading_deg>0</heading_deg>
            </spherical_coordinates>
            <physics name="1ms" type="ode">

                <max_step_size>0.01</max_step_size>
                <real_time_factor>1.0</real_time_factor>

                  <ode>
                    <solver>
                      <type>quick</type>
                      <iters>200</iters>
                      <precon_iters>0</precon_iters>
                      <sor>1.4</sor>
                      <use_dynamic_moi_rescaling>1</use_dynamic_moi_rescaling>
                    </solver>
                    <constraints>
                      <cfm>0.000000</cfm>
                      <erp>0.8</erp>
                      <contact_max_correcting_vel>2000.000000</contact_max_correcting_vel>
                      <contact_surface_layer>0.01000</contact_surface_layer>
                    </constraints>
                </ode>

            </physics>
            <plugin
                filename="gz-sim-physics-system"
                name="gz::sim::systems::Physics">
            </plugin>
            <plugin
                filename="gz-sim-user-commands-system"
                name="gz::sim::systems::UserCommands">
            </plugin>
            <plugin
                filename="gz-sim-scene-broadcaster-system"
                name="gz::sim::systems::SceneBroadcaster">
            </plugin>

            <light type="directional" name="sun">
                <cast_shadows>true</cast_shadows>
                <pose>0 0 10 0 0 0</pose>
                <diffuse>0.8 0.8 0.8 1</diffuse>
                <specular>0.2 0.2 0.2 1</specular>
                <attenuation>
                    <range>1000</range>
                    <constant>0.9</constant>
                    <linear>0.01</linear>
                    <quadratic>0.001</quadratic>
                </attenuation>
                <direction>-0.5 0.1 -0.9</direction>
            </light>

            <model name="ground_plane">
                <static>true</static>
                <pose relative_to='world'>0 0 0.08 0 0 0</pose>-->
                <link name="link">
                    <collision name="collision">
                        <geometry>
                            <plane>
                            <normal>0 0 1</normal>
                            </plane>
                        </geometry>
                    </collision>
                    <visual name="visual">
                        <geometry>
                            <plane>
                            <normal>0 0 1</normal>
                            <size>1000 1000</size>
                            </plane>
                        </geometry>
                    <material>
                        <ambient>0.365 0.631 0.188 1</ambient>
                        <diffuse>0.365 0.631 0.188 1</diffuse>
                        <specular>0.365 0.631 0.188 1</specular>
                    </material>
                    </visual>
                </link>
            </model>

<!--            <model name="polygon">-->
<!--                <static>true</static>-->
<!--                <pose relative_to='world'>-3 0 0 0 0 0</pose>-->
<!--                <link name="link">-->
<!--                    <visual name='visual'>-->
<!--                        <geometry>-->
<!--                            <mesh>-->
<!--                                <scale>1 1 1</scale>-->
<!--                                <uri>meshes/v3/polygon.dae</uri>-->
<!--                            </mesh>-->
<!--                        </geometry>-->
<!--                    </visual>-->
<!--                    <collision name='collision'>-->
<!--                        <geometry>-->
<!--                            <mesh>-->
<!--                                <scale>1 1 1</scale>-->
<!--                                <uri>meshes/v3/polygon.dae</uri>-->
<!--                            </mesh>-->
<!--                        </geometry>-->
<!--                    </collision>-->
<!--                </link>-->
<!--            </model>-->

<!--            <model name="wheat">-->
<!--                <static>true</static>-->
<!--                <pose relative_to='polygon'>0 0 0 0 0 0</pose>-->
<!--                <link name="link">-->
<!--                    <visual name='visual'>-->
<!--                        <geometry>-->
<!--                            <mesh>-->
<!--                                <scale>1 1 1</scale>-->
<!--                                <uri>meshes/v3/wheat.dae</uri>-->
<!--                            </mesh>-->
<!--                        </geometry>-->
<!--                    </visual>-->
<!--                </link>-->
<!--            </model>-->


            <!-- ////////////////////////////-->
            <!-- ////////////////////////////-->
            <!-- ROBOT MODEL -->
            <!-- ////////////////////////////-->
            <!-- ////////////////////////////-->

            <model name='agro_bot' canonical_link='base_link'>
                <pose relative_to='world'>0 0 0 0 0 0</pose>

                <!-- ////////////////////////////-->
                <!-- ////////////////////////////-->
                <!-- BASE LINK -->
                <!-- ////////////////////////////-->
                <!-- ////////////////////////////-->
                <link name='base_link'>
                    <pose relative_to='__model__'>0 0 1.06 0 0 0</pose>
                    <inertial>
                        <mass>250</mass>
                        <inertia>
                            <ixx>0.126164</ixx>
                            <ixy>0</ixy>
                            <ixz>0</ixz>
                            <iyy>0.416519</iyy>
                            <iyz>0</iyz>
                            <izz>0.481014</izz>
                        </inertia>
                    </inertial>
                    <visual name='visual'>
                        <geometry>
                            <mesh>
                                <scale>1 1 1</scale>
                                <uri>meshes/v3/base_link.STL</uri>
                            </mesh>
                        </geometry>
                        <material>
                            <ambient>0.2 0.2 0.2 1</ambient>
                            <diffuse>0.2 0.2 0.2 1</diffuse>
                            <specular>0.2 0.2 0.2 1</specular>
                        </material>
                    </visual>
                    <collision name='collision'>
                        <geometry>
                            <mesh>
                                <scale>1 1 1</scale>
                                <uri>meshes/v3/base_link.STL</uri>
                            </mesh>
                        </geometry>
                    </collision>
                    <sensor name="navsat" type="navsat">
                        <gz_frame_id>navsat</gz_frame_id>
                        <always_on>1</always_on>
                        <update_rate>1</update_rate>
                        <topic>navsat</topic>
                    </sensor>
                    <sensor name="imu_sensor" type="imu">
                        <gz_frame_id>imu</gz_frame_id>
                        <always_on>1</always_on>
                        <update_rate>1</update_rate>
                        <visualize>true</visualize>
                        <topic>imu</topic>
                    </sensor>
                </link>

                <!-- ////////////////////////////-->
                <!-- ////////////////////////////-->
                <!-- NAVIGATION LINK -->
                <!-- ////////////////////////////-->
                <!-- ////////////////////////////-->
                <link name='navigation_link'>
                    <pose relative_to='base_link'>0 0 0 0 0 0</pose>
                    <inertial>
                        <mass>0.5</mass>
                        <inertia>
                            <ixx>0.126164</ixx>
                            <ixy>0</ixy>
                            <ixz>0</ixz>
                            <iyy>0.416519</iyy>
                            <iyz>0</iyz>
                            <izz>0.481014</izz>
                        </inertia>
                    </inertial>
                    <visual name='visual'>
                        <geometry>
                            <box>
                                <size>0.1 0.1 0.1</size>
                            </box>
                        </geometry>
                        <material>
                            <ambient>0.2 0.2 0.2 1</ambient>
                            <diffuse>0.2 0.2 0.2 1</diffuse>
                            <specular>0.2 0.2 0.2 1</specular>
                        </material>
                    </visual>
                    <collision name='collision'>
                        <geometry>
                            <box>
                                <size>0.1 0.1 0.1</size>
                            </box>
                        </geometry>
                    </collision>
                    <sensor name="navsat" type="navsat">
                        <gz_frame_id>navsat</gz_frame_id>
                        <always_on>1</always_on>
                        <update_rate>10</update_rate>
                        <topic>navsat</topic>
                    </sensor>
                    <sensor name="imu_sensor" type="imu">
                        <gz_frame_id>imu</gz_frame_id>
                        <always_on>1</always_on>
                        <update_rate>10</update_rate>
                        <visualize>true</visualize>
                        <topic>imu</topic>
                    </sensor>
                </link>

                <joint name='navigation_joint' type='fixed'>
                   <pose relative_to='navigation_link'>0 0 0 0 0 0</pose>
                    <parent>base_link</parent>
                    <child>navigation_link</child>
                </joint>

                <!-- ////////////////////////////-->
                <!-- ////////////////////////////-->
                <!-- FRONT CAMERA LINK -->
                <!-- ////////////////////////////-->
                <!-- ////////////////////////////-->
                <link name='front_camera_link'>
                    <pose relative_to='base_link'>0.3 0 0.5 0 0 0</pose>
                    <inertial>
                        <mass>0.5</mass>
                        <inertia>
                            <ixx>0.126164</ixx>
                            <ixy>0</ixy>
                            <ixz>0</ixz>
                            <iyy>0.416519</iyy>
                            <iyz>0</iyz>
                            <izz>0.481014</izz>
                        </inertia>
                    </inertial>
                    <visual name='visual'>
                        <geometry>
                            <box>
                                <size>0.05 0.15 0.05</size>
                            </box>
                        </geometry>
                        <material>
                            <ambient>0.2 0.2 0.2 1</ambient>
                            <diffuse>0.2 0.2 0.2 1</diffuse>
                            <specular>0.2 0.2 0.2 1</specular>
                        </material>
                    </visual>
                    <collision name='collision'>
                        <geometry>
                            <box>
                                <size>0.05 0.15 0.05</size>
                            </box>
                        </geometry>
                    </collision>

                    <sensor name="depth" type="depth_camera">
                      <gz_frame_id>front_camera_link</gz_frame_id>
                      <update_rate>10</update_rate>
                      <topic>front_camera/depth</topic>
                      <camera>
                        <horizontal_fov>1.05</horizontal_fov>
                        <image>
                          <width>1280</width>
                          <height>720</height>
                          <format>R_FLOAT32</format>
                        </image>
                        <clip>
                          <near>0.01</near>
                          <far>32.0</far>
                        </clip>
                      </camera>
                   </sensor>
                   <sensor name="rgb" type="camera">
                      <gz_frame_id>front_camera_link</gz_frame_id>
                      <topic>front_camera/color</topic>
                      <camera>
                        <horizontal_fov>1.05</horizontal_fov>
                        <image>
                          <width>1280</width>
                          <height>720</height>
                        </image>
                        <clip>
                          <near>0.1</near>
                          <far>100</far>
                        </clip>
                      </camera>
                      <always_on>1</always_on>
                      <update_rate>30</update_rate>
                      <visualize>true</visualize>
                   </sensor>
                   <sensor name='gpu_lidar' type='gpu_lidar'>"
                        <gz_frame_id>front_camera_link</gz_frame_id>
                        <pose relative_to='front_camera_link'>0 0 0 0 0 0</pose>
                        <topic>front_camera/scan</topic>
                        <update_rate>1</update_rate>
                        <ray>
                            <scan>
                                <horizontal>
                                    <samples>320</samples>
                                    <resolution>1</resolution>
                                    <min_angle>-0.52</min_angle>
                                    <max_angle>0.52</max_angle>
                                </horizontal>
                                <vertical>
                                    <samples>32</samples>
                                    <resolution>1</resolution>
                                    <min_angle>-0.261791667</min_angle>
                                    <max_angle>0.261791667</max_angle>
                                </vertical>
                            </scan>
                            <range>
                                <min>0.5</min>
                                <max>32.0</max>
                                <resolution>0.01</resolution>
                            </range>
                        </ray>
                        <always_on>1</always_on>
                        <visualize>true</visualize>
                   </sensor>
                </link>

                <joint name='front_camera_joint' type='fixed'>
                   <pose relative_to='base_link'>0.3 0 0.5 0 0 0</pose>
                    <parent>base_link</parent>
                    <child>front_camera_link</child>
                </joint>

                <!-- ////////////////////////////-->
                <!-- ////////////////////////////-->
                <!-- REAR CAMERA LINK -->
                <!-- ////////////////////////////-->
                <!-- ////////////////////////////-->
                <link name='rear_camera_link'>
                    <pose relative_to='base_link'>-0.3 0 0.5 0 0 3.14</pose>
                    <inertial>
                        <mass>0.5</mass>
                        <inertia>
                            <ixx>0.126164</ixx>
                            <ixy>0</ixy>
                            <ixz>0</ixz>
                            <iyy>0.416519</iyy>
                            <iyz>0</iyz>
                            <izz>0.481014</izz>
                        </inertia>
                    </inertial>
                    <visual name='visual'>
                        <geometry>
                            <box>
                                <size>0.05 0.15 0.05</size>
                            </box>
                        </geometry>
                        <material>
                            <ambient>0.2 0.2 0.2 1</ambient>
                            <diffuse>0.2 0.2 0.2 1</diffuse>
                            <specular>0.2 0.2 0.2 1</specular>
                        </material>
                    </visual>
                    <collision name='collision'>
                        <geometry>
                            <box>
                                <size>0.05 0.15 0.05</size>
                            </box>
                        </geometry>
                    </collision>

                    <sensor name="depth" type="depth_camera">
                      <gz_frame_id>rear_camera_link</gz_frame_id>
                      <update_rate>10</update_rate>
                      <topic>rear_camera/depth</topic>
                      <camera>
                        <horizontal_fov>1.05</horizontal_fov>
                        <image>
                          <width>1280</width>
                          <height>720</height>
                          <format>R_FLOAT32</format>
                        </image>
                        <clip>
                          <near>0.01</near>
                          <far>32.0</far>
                        </clip>
                      </camera>
                   </sensor>
                   <sensor name="rgb" type="camera">
                      <gz_frame_id>rear_camera_link</gz_frame_id>
                      <topic>rear_camera/color</topic>
                      <camera>
                        <horizontal_fov>1.05</horizontal_fov>
                        <image>
                          <width>1280</width>
                          <height>720</height>
                        </image>
                        <clip>
                          <near>0.1</near>
                          <far>100</far>
                        </clip>
                      </camera>
                      <always_on>1</always_on>
                      <update_rate>30</update_rate>
                      <visualize>true</visualize>
                   </sensor>
                   <sensor name='gpu_lidar' type='gpu_lidar'>"
                        <gz_frame_id>rear_camera_link</gz_frame_id>
                        <pose relative_to='rear_camera_link'>0 0 0 0 0 0</pose>
                        <topic>rear_camera/scan</topic>
                        <update_rate>1</update_rate>
                        <ray>
                            <scan>
                                <horizontal>
                                    <samples>320</samples>
                                    <resolution>1</resolution>
                                    <min_angle>-0.33</min_angle>
                                    <max_angle>0.33</max_angle>
                                </horizontal>
                                <vertical>
                                    <samples>32</samples>
                                    <resolution>1</resolution>
                                    <min_angle>-0.261791667</min_angle>
                                    <max_angle>0.261791667</max_angle>
                                </vertical>
                            </scan>
                            <range>
                                <min>0.5</min>
                                <max>32.0</max>
                                <resolution>0.01</resolution>
                            </range>
                        </ray>
                        <always_on>1</always_on>
                        <visualize>true</visualize>
                   </sensor>
                </link>

                <joint name='rear_camera_joint' type='fixed'>
                   <pose relative_to='base_link'>-0.3 0 0.5 0 0 3.14</pose>
                    <parent>base_link</parent>
                    <child>rear_camera_link</child>
                </joint>

                <!-- ////////////////////////////-->
                <!-- ////////////////////////////-->
                <!-- LEFT CAMERA LINK -->
                <!-- ////////////////////////////-->
                <!-- ////////////////////////////-->
                <link name='left_camera_link'>
                    <pose relative_to='base_link'>0 0.3 0.5 0 0 1.57</pose>
                    <inertial>
                        <mass>0.5</mass>
                        <inertia>
                            <ixx>0.126164</ixx>
                            <ixy>0</ixy>
                            <ixz>0</ixz>
                            <iyy>0.416519</iyy>
                            <iyz>0</iyz>
                            <izz>0.481014</izz>
                        </inertia>
                    </inertial>
                    <visual name='visual'>
                        <geometry>
                            <box>
                                <size>0.05 0.15 0.05</size>
                            </box>
                        </geometry>
                        <material>
                            <ambient>0.2 0.2 0.2 1</ambient>
                            <diffuse>0.2 0.2 0.2 1</diffuse>
                            <specular>0.2 0.2 0.2 1</specular>
                        </material>
                    </visual>
                    <collision name='collision'>
                        <geometry>
                            <box>
                                <size>0.05 0.15 0.05</size>
                            </box>
                        </geometry>
                    </collision>

                    <sensor name="depth" type="depth_camera">
                      <gz_frame_id>left_camera_link</gz_frame_id>
                      <update_rate>10</update_rate>
                      <topic>left_camera/depth</topic>
                      <camera>
                        <horizontal_fov>1.05</horizontal_fov>
                        <image>
                          <width>1280</width>
                          <height>720</height>
                          <format>R_FLOAT32</format>
                        </image>
                        <clip>
                          <near>0.01</near>
                          <far>32.0</far>
                        </clip>
                      </camera>
                   </sensor>
                   <sensor name="rgb" type="camera">
                      <gz_frame_id>left_camera_link</gz_frame_id>
                      <topic>left_camera/color</topic>
                      <camera>
                        <horizontal_fov>1.05</horizontal_fov>
                        <image>
                          <width>1280</width>
                          <height>720</height>
                        </image>
                        <clip>
                          <near>0.1</near>
                          <far>100</far>
                        </clip>
                      </camera>
                      <always_on>1</always_on>
                      <update_rate>30</update_rate>
                      <visualize>true</visualize>
                   </sensor>
                   <sensor name='gpu_lidar' type='gpu_lidar'>"
                        <gz_frame_id>left_camera_link</gz_frame_id>
                        <pose relative_to='left_camera_link'>0 0 0 0 0 0</pose>
                        <topic>left_camera/scan</topic>
                        <update_rate>1</update_rate>
                        <ray>
                            <scan>
                                <horizontal>
                                    <samples>320</samples>
                                    <resolution>1</resolution>
                                    <min_angle>-0.33</min_angle>
                                    <max_angle>0.33</max_angle>
                                </horizontal>
                                <vertical>
                                    <samples>32</samples>
                                    <resolution>1</resolution>
                                    <min_angle>-0.261791667</min_angle>
                                    <max_angle>0.261791667</max_angle>
                                </vertical>
                            </scan>
                            <range>
                                <min>0.5</min>
                                <max>32.0</max>
                                <resolution>0.01</resolution>
                            </range>
                        </ray>
                        <always_on>1</always_on>
                        <visualize>true</visualize>
                   </sensor>
                </link>

                <joint name='left_camera_joint' type='fixed'>
                   <pose relative_to='base_link'>0 0.3 0.5 0 0 1.57</pose>
                    <parent>base_link</parent>
                    <child>left_camera_link</child>
                </joint>

                <!-- ////////////////////////////-->
                <!-- ////////////////////////////-->
                <!-- RIGHT CAMERA LINK -->
                <!-- ////////////////////////////-->
                <!-- ////////////////////////////-->
                <link name='right_camera_link'>
                    <pose relative_to='base_link'>0 -0.3 0.5 0 0 -1.57</pose>
                    <inertial>
                        <mass>0.5</mass>
                        <inertia>
                            <ixx>0.126164</ixx>
                            <ixy>0</ixy>
                            <ixz>0</ixz>
                            <iyy>0.416519</iyy>
                            <iyz>0</iyz>
                            <izz>0.481014</izz>
                        </inertia>
                    </inertial>
                    <visual name='visual'>
                        <geometry>
                            <box>
                                <size>0.05 0.15 0.05</size>
                            </box>
                        </geometry>
                        <material>
                            <ambient>0.2 0.2 0.2 1</ambient>
                            <diffuse>0.2 0.2 0.2 1</diffuse>
                            <specular>0.2 0.2 0.2 1</specular>
                        </material>
                    </visual>
                    <collision name='collision'>
                        <geometry>
                            <box>
                                <size>0.05 0.15 0.05</size>
                            </box>
                        </geometry>
                    </collision>

                    <sensor name="depth" type="depth_camera">
                      <gz_frame_id>right_camera_link</gz_frame_id>
                      <update_rate>10</update_rate>
                      <topic>right_camera/depth</topic>
                      <camera>
                        <horizontal_fov>1.05</horizontal_fov>
                        <image>
                          <width>1280</width>
                          <height>720</height>
                          <format>R_FLOAT32</format>
                        </image>
                        <clip>
                          <near>0.01</near>
                          <far>32.0</far>
                        </clip>
                      </camera>
                   </sensor>
                   <sensor name="rgb" type="camera">
                      <gz_frame_id>right_camera_link</gz_frame_id>
                      <topic>right_camera/color</topic>
                      <camera>
                        <horizontal_fov>1.05</horizontal_fov>
                        <image>
                          <width>1280</width>
                          <height>720</height>
                        </image>
                        <clip>
                          <near>0.1</near>
                          <far>100</far>
                        </clip>
                      </camera>
                      <always_on>1</always_on>
                      <update_rate>30</update_rate>
                      <visualize>true</visualize>
                   </sensor>
                   <sensor name='gpu_lidar' type='gpu_lidar'>"
                        <gz_frame_id>right_camera_link</gz_frame_id>
                        <pose relative_to='right_camera_link'>0 0 0 0 0 0</pose>
                        <topic>right_camera/scan</topic>
                        <update_rate>1</update_rate>
                        <ray>
                            <scan>
                                <horizontal>
                                    <samples>320</samples>
                                    <resolution>1</resolution>
                                    <min_angle>-0.33</min_angle>
                                    <max_angle>0.33</max_angle>
                                </horizontal>
                                <vertical>
                                    <samples>32</samples>
                                    <resolution>1</resolution>
                                    <min_angle>-0.261791667</min_angle>
                                    <max_angle>0.261791667</max_angle>
                                </vertical>
                            </scan>
                            <range>
                                <min>0.5</min>
                                <max>32.0</max>
                                <resolution>0.01</resolution>
                            </range>
                        </ray>
                        <always_on>1</always_on>
                        <visualize>true</visualize>
                   </sensor>
                </link>

                <joint name='right_camera_joint' type='fixed'>
                   <pose relative_to='base_link'>0 -0.3 0.5 0 0 -1.57</pose>
                    <parent>base_link</parent>
                    <child>right_camera_link</child>
                </joint>

                <!-- ////////////////////////////-->
                <!-- ////////////////////////////-->
                <!-- BASE FOOTPRINT LINK -->
                <!-- ////////////////////////////-->
                <!-- ////////////////////////////-->
                <link name='base_footprint'>
                    <pose relative_to='base_link'>0 0 -1 0 0 0</pose>
                </link>

                <joint name='base_footprint_joint' type='fixed'>
                   <pose relative_to='base_link'>0 0 -1 0 0 0</pose>
                    <parent>base_link</parent>
                    <child>base_footprint</child>
                </joint>

                <!-- ////////////////////////////-->
                <!-- ////////////////////////////-->
                <!-- FRONT LEFT STEERING -->
                <!-- ////////////////////////////-->
                <!-- ////////////////////////////-->
                <link name='front_left_steering'>
                    <pose relative_to='base_link'>0.81000 1.05393 -0.38515 0 0 3.1415</pose>
                    <inertial>
                        <mass>20</mass>
                        <inertia>
                            <ixx>0.01</ixx>
                            <ixy>0.00</ixy>
                            <ixz>0.00</ixz>
                            <iyx>0.00</iyx>
                            <iyy>0.01</iyy>
                            <iyz>0.00</iyz>
                            <izx>0.00</izx>
                            <izy>0.00</izy>
                            <izz>0.01</izz>
                        </inertia>
                    </inertial>
                    <visual name='visual'>
                        <geometry>
                            <mesh>
                                <scale>1 1 1</scale>
                                <uri>meshes/v3/steering.STL</uri>
                            </mesh>
                        </geometry>
                        <material>
                            <ambient>0.25 0.25 0.25 1</ambient>
                            <diffuse>0.25 0.25 0.25 1</diffuse>
                            <specular>0.25 0.25 0.25 1</specular>
                        </material>
                    </visual>
                    <collision name='collision'>
                        <geometry>
                            <mesh>
                                <scale>1 1 1</scale>
                                <uri>meshes/v3/steering.STL</uri>
                            </mesh>
                        </geometry>
                    </collision>
                </link>

                <joint name='front_left_steering_joint' type='revolute'>
                   <pose relative_to='base_link'>0.78500 1.0500 -0.38515 0 0 3.1415</pose>
                    <parent>base_link</parent>
                    <child>front_left_steering</child>
                    <axis>
                        <xyz expressed_in='__model__'>0 0 1</xyz>
                        <limit>
                            <lower>-6.28</lower>
                            <upper>6.28</upper>
                            <velocity>1.79769e+308</velocity>
                            <effort>1.79769e+308</effort>
                        </limit>
                        <dynamics>
                            <damping>20.0</damping>
                            <friction>0.01</friction>
                            <spring_reference>2</spring_reference>
                        </dynamics>
                        <physics>
                            <ode>
                                <cfm>1</cfm>
                                <erp>1</erp>
                                <max_force>1.79769e+308</max_force>
                                <velocity>1.79769e+308</velocity>
                            </ode>
                        </physics>
                    </axis>
                </joint>

                <!-- ////////////////////////////-->
                <!-- ////////////////////////////-->
                <!-- FRONT LEFT-LEFT BEAM -->
                <!-- ////////////////////////////-->
                <!-- ////////////////////////////-->
                <link name='front_left_left_beam'>
                    <pose relative_to='front_left_steering'>0.0075 -0.055 -0.31 0 0 0</pose>
                    <inertial>
                        <mass>2</mass>
                        <inertia>
                            <ixx>1.00</ixx>
                            <ixy>0.04</ixy>
                            <ixz>-0.04</ixz>
                            <iyx>-0.05</iyx>
                            <iyy>0.99</iyy>
                            <iyz>-0.11</iyz>
                            <izx>0.04</izx>
                            <izy>0.11</izy>
                            <izz>0.99</izz>
                        </inertia>
                    </inertial>
                    <visual name='visual'>
                        <geometry>
                            <mesh>
                                <scale>1 1 1</scale>
                                <uri>meshes/v3/beam.STL</uri>
                            </mesh>
                        </geometry>
                        <material>
                            <ambient>0.25 0.25 0.25 1</ambient>
                            <diffuse>0.25 0.25 0.25 1</diffuse>
                            <specular>0.25 0.25 0.25 1</specular>
                        </material>
                    </visual>
                    <collision name='collision'>
                        <geometry>
                            <mesh>
                                <scale>1 1 1</scale>
                                <uri>meshes/v3/beam.STL</uri>
                            </mesh>
                        </geometry>
                    </collision>
                </link>

                <joint name='front_left_left_beam_joint' type='revolute'>
                   <pose relative_to='front_left_steering'>-0.09363 -0.055 -0.29706 0 0 0</pose>
                    <parent>front_left_steering</parent>
                    <child>front_left_left_beam</child>
                    <axis>
                        <xyz expressed_in='__model__'>0 1 0</xyz>
                        <limit>
                            <lower>-0.9</lower>
                            <upper>0.9</upper>
                            <velocity>10</velocity>
                        </limit>
                        <dynamics>
                            <damping>15</damping>
                            <friction>0.6</friction>
                            <spring_reference>0.06</spring_reference>
                            <spring_stiffness>590</spring_stiffness> <!-- Жесткость пружины -->
                        </dynamics>
                    </axis>
                </joint>

                <!-- ////////////////////////////-->
                <!-- ////////////////////////////-->
                <!-- FRONT LEFT-LEFT WHEEL -->
                <!-- ////////////////////////////-->
                <!-- ////////////////////////////-->
                <link name='front_left_left_wheel'>
                    <pose relative_to='front_left_left_beam'>0.00748 -0.065 -0.047 0 0 0</pose>
                    <inertial>
                        <mass>18</mass>
                        <inertia>
                            <ixx>0.1</ixx>
                            <ixy>0.00</ixy>
                            <ixz>0.00</ixz>
                            <iyx>0.00</iyx>
                            <iyy>0.1</iyy>
                            <iyz>0.00</iyz>
                            <izx>0.00</izx>
                            <izy>0.00</izy>
                            <izz>0.2</izz>
                        </inertia>
                    </inertial>
                    <visual name='visual'>
                        <geometry>
                            <mesh>
                                <scale>1 1 1</scale>
                                <uri>meshes/v3/wheel.STL</uri>
                            </mesh>
                        </geometry>
                        <material>
                            <ambient>0.0 0.0 0.0 1</ambient>
                            <diffuse>0.0 0.0 0.0 1</diffuse>
                            <specular>0.0 0.0 0.0 1</specular>
                        </material>
                    </visual>
                    <collision name='collision'>
                        <geometry>
                            <mesh>
                                <scale>1 1 1</scale>
                                <uri>meshes/v3/wheel.STL</uri>
                            </mesh>
                        </geometry>
                        <surface>
                            <friction>
                              <ode>
                                <mu>0.5</mu>
                                <mu2>1.0</mu2>
                                <fdir1>0 0 1</fdir1>
                              </ode>
                              <bullet>
                                <friction>0.5</friction>
                                <friction2>1</friction2>
                                <rolling_friction>0.1</rolling_friction>
                              </bullet>
                            </friction>
                        </surface>
                    </collision>
                </link>

                <joint name='front_left_left_wheel_joint' type='revolute'>
                   <pose relative_to='front_left_left_beam'>0.00748 -0.05 -0.047 0 0 0</pose>
                    <parent>front_left_left_beam</parent>
                    <child>front_left_left_wheel</child>
                    <axis>
                        <xyz expressed_in='__model__'>0 1 0</xyz>
                        <limit>
                            <lower>-1.79769e+308</lower>
                            <upper>1.79769e+308</upper>
                            <velocity>1.79769e+308</velocity>
                            <effort>1.79769e+308</effort>
                        </limit>
                    </axis>
                </joint>

                <!-- ////////////////////////////-->
                <!-- ////////////////////////////-->
                <!-- FRONT LEFT-RIGHT BEAM -->
                <!-- ////////////////////////////-->
                <!-- ////////////////////////////-->
                <link name='front_left_right_beam'>
                    <pose relative_to='front_left_steering'>0.0075 0.055 -0.31 0 0 0</pose>
                    <inertial>
                        <mass>2</mass>
                        <inertia>
                            <ixx>1.00</ixx>
                            <ixy>0.04</ixy>
                            <ixz>-0.04</ixz>
                            <iyx>-0.05</iyx>
                            <iyy>0.99</iyy>
                            <iyz>-0.11</iyz>
                            <izx>0.04</izx>
                            <izy>0.11</izy>
                            <izz>0.99</izz>
                        </inertia>
                    </inertial>
                    <visual name='visual'>
                        <geometry>
                            <mesh>
                                <scale>1 1 1</scale>
                                <uri>meshes/v3/beam.STL</uri>
                            </mesh>
                        </geometry>
                        <material>
                            <ambient>0.25 0.25 0.25 1</ambient>
                            <diffuse>0.25 0.25 0.25 1</diffuse>
                            <specular>0.25 0.25 0.25 1</specular>
                        </material>
                    </visual>
                    <collision name='collision'>
                        <geometry>
                            <mesh>
                                <scale>1 1 1</scale>
                                <uri>meshes/v3/beam.STL</uri>
                            </mesh>
                        </geometry>
                    </collision>
                </link>

                <joint name='front_left_right_beam_joint' type='revolute'>
                   <pose relative_to='front_left_steering'>-0.09363 0.055 -0.29706 0 0 0</pose>
                    <parent>front_left_steering</parent>
                    <child>front_left_right_beam</child>
                    <axis>
                        <xyz expressed_in='__model__'>0 1 0</xyz>
                        <limit>
                            <lower>-0.9</lower>
                            <upper>0.9</upper>
                            <velocity>10</velocity>
                        </limit>
                        <dynamics>
                            <damping>15</damping>
                            <friction>0.6</friction>
                            <spring_reference>0.06</spring_reference>
                            <spring_stiffness>590</spring_stiffness> <!-- Жесткость пружины -->
                        </dynamics>
                    </axis>
                </joint>

                <!-- ////////////////////////////-->
                <!-- ////////////////////////////-->
                <!-- FRONT LEFT-RIGHT WHEEL -->
                <!-- ////////////////////////////-->
                <!-- ////////////////////////////-->
                <link name='front_left_right_wheel'>
                    <pose relative_to='front_left_right_beam'>0.00748 0.065 -0.047 0 0 3.1415</pose>
                    <inertial>
                        <mass>18</mass>
                        <inertia>
                            <ixx>0.1</ixx>
                            <ixy>0.00</ixy>
                            <ixz>0.00</ixz>
                            <iyx>0.00</iyx>
                            <iyy>0.1</iyy>
                            <iyz>0.00</iyz>
                            <izx>0.00</izx>
                            <izy>0.00</izy>
                            <izz>0.2</izz>
                        </inertia>
                    </inertial>
                    <visual name='visual'>
                        <geometry>
                            <mesh>
                                <scale>1 1 1</scale>
                                <uri>meshes/v3/wheel.STL</uri>
                            </mesh>
                        </geometry>
                        <material>
                            <ambient>0.1 0.1 0.1 1</ambient>
                            <diffuse>0.1 0.1 0.1 1</diffuse>
                            <specular>0.1 0.1 0.1 1</specular>
                        </material>
                    </visual>
                    <collision name='collision'>
                        <geometry>
                            <mesh>
                                <scale>1 1 1</scale>
                                <uri>meshes/v3/wheel.STL</uri>
                            </mesh>
                        </geometry>
                    </collision>
                    <surface>
                            <friction>
                              <ode>
                                <mu>0.5</mu>
                                <mu2>1.0</mu2>
                                <fdir1>0 0 1</fdir1>
                              </ode>
                              <bullet>
                                <friction>0.5</friction>
                                <friction2>1</friction2>
                                <rolling_friction>0.1</rolling_friction>
                              </bullet>
                            </friction>
                        </surface>
                </link>

                <joint name='front_left_right_wheel_joint' type='revolute'>
                   <pose relative_to='front_left_right_beam'>0.00748 0.05 -0.047 0 0 0</pose>
                    <parent>front_left_right_beam</parent>
                    <child>front_left_right_wheel</child>
                    <axis>
                        <xyz expressed_in='__model__'>0 1 0</xyz>
                        <limit>
                            <lower>-1.79769e+308</lower>
                            <upper>1.79769e+308</upper>
                            <velocity>1.79769e+308</velocity>
                            <effort>1.79769e+308</effort>
                        </limit>
                    </axis>
                </joint>

                <!-- ////////////////////////////-->
                <!-- ////////////////////////////-->
                <!-- FRONT RIGHT STEERING -->
                <!-- ////////////////////////////-->
                <!-- ////////////////////////////-->
                <link name='front_right_steering'>
                    <pose relative_to='base_link'>0.81000 -1.05393 -0.38515 0 0 3.1415</pose>
                    <inertial>
                        <mass>20</mass>
                        <inertia>
                            <ixx>0.01</ixx>
                            <ixy>0.00</ixy>
                            <ixz>0.00</ixz>
                            <iyx>0.00</iyx>
                            <iyy>0.01</iyy>
                            <iyz>0.00</iyz>
                            <izx>0.00</izx>
                            <izy>0.00</izy>
                            <izz>0.01</izz>
                        </inertia>
                    </inertial>
                    <visual name='visual'>
                        <geometry>
                            <mesh>
                                <scale>1 1 1</scale>
                                <uri>meshes/v3/steering.STL</uri>
                            </mesh>
                        </geometry>
                        <material>
                            <ambient>0.25 0.25 0.25 1</ambient>
                            <diffuse>0.25 0.25 0.25 1</diffuse>
                            <specular>0.25 0.25 0.25 1</specular>
                        </material>
                    </visual>
                    <collision name='collision'>
                        <geometry>
                            <mesh>
                                <scale>1 1 1</scale>
                                <uri>meshes/v3/steering.STL</uri>
                            </mesh>
                        </geometry>
                    </collision>
                </link>

                <joint name='front_right_steering_joint' type='revolute'>
                   <pose relative_to='base_link'>0.78500 -1.0500 -0.38515 0 0 3.1415</pose>
                    <parent>base_link</parent>
                    <child>front_right_steering</child>
                    <axis>
                        <xyz expressed_in='__model__'>0 0 1</xyz>
                        <limit>
                            <lower>-6.28</lower>
                            <upper>6.28</upper>
                            <velocity>1.79769e+308</velocity>
                            <effort>1.79769e+308</effort>
                        </limit>
                        <dynamics>
                            <damping>20.0</damping>
                            <friction>0.01</friction>
                            <spring_reference>2</spring_reference>
                        </dynamics>
                        <physics>
                            <ode>
                                <cfm>1</cfm>
                                <erp>1</erp>
                                <max_force>1.79769e+308</max_force>
                                <velocity>1.79769e+308</velocity>
                            </ode>
                        </physics>
                    </axis>
                </joint>

                <!-- ////////////////////////////-->
                <!-- ////////////////////////////-->
                <!-- FRONT RIGHT-LEFT BEAM -->
                <!-- ////////////////////////////-->
                <!-- ////////////////////////////-->
                <link name='front_right_left_beam'>
                    <pose relative_to='front_right_steering'>0.0075 -0.055 -0.31 0 0 0</pose>
                    <inertial>
                        <mass>2</mass>
                        <inertia>
                            <ixx>1.00</ixx>
                            <ixy>0.04</ixy>
                            <ixz>-0.04</ixz>
                            <iyx>-0.05</iyx>
                            <iyy>0.99</iyy>
                            <iyz>-0.11</iyz>
                            <izx>0.04</izx>
                            <izy>0.11</izy>
                            <izz>0.99</izz>
                        </inertia>
                    </inertial>
                    <visual name='visual'>
                        <geometry>
                            <mesh>
                                <scale>1 1 1</scale>
                                <uri>meshes/v3/beam.STL</uri>
                            </mesh>
                        </geometry>
                        <material>
                            <ambient>0.25 0.25 0.25 1</ambient>
                            <diffuse>0.25 0.25 0.25 1</diffuse>
                            <specular>0.25 0.25 0.25 1</specular>
                        </material>
                    </visual>
                    <collision name='collision'>
                        <geometry>
                            <mesh>
                                <scale>1 1 1</scale>
                                <uri>meshes/v3/beam.STL</uri>
                            </mesh>
                        </geometry>
                    </collision>
                </link>

                <joint name='front_right_left_beam_joint' type='revolute'>
                   <pose relative_to='front_right_steering'>-0.09363 -0.055 -0.29706 0 0 0</pose>
                    <parent>front_right_steering</parent>
                    <child>front_right_left_beam</child>
                    <axis>
                        <xyz expressed_in='__model__'>0 1 0</xyz>
                        <limit>
                            <lower>-0.9</lower>
                            <upper>0.9</upper>
                            <velocity>10</velocity>
                        </limit>
                        <dynamics>
                            <damping>15</damping>
                            <friction>0.6</friction>
                            <spring_reference>0.06</spring_reference>
                            <spring_stiffness>590</spring_stiffness> <!-- Жесткость пружины -->
                        </dynamics>
                    </axis>
                </joint>

                <!-- ////////////////////////////-->
                <!-- ////////////////////////////-->
                <!-- FRONT RIGHT-LEFT WHEEL -->
                <!-- ////////////////////////////-->
                <!-- ////////////////////////////-->
                <link name='front_right_left_wheel'>
                    <pose relative_to='front_right_left_beam'>0.00748 -0.065 -0.047 0 0 0</pose>
                    <inertial>
                        <mass>18</mass>
                        <inertia>
                            <ixx>0.1</ixx>
                            <ixy>0.00</ixy>
                            <ixz>0.00</ixz>
                            <iyx>0.00</iyx>
                            <iyy>0.1</iyy>
                            <iyz>0.00</iyz>
                            <izx>0.00</izx>
                            <izy>0.00</izy>
                            <izz>0.2</izz>
                        </inertia>
                    </inertial>
                    <visual name='visual'>
                        <geometry>
                            <mesh>
                                <scale>1 1 1</scale>
                                <uri>meshes/v3/wheel.STL</uri>
                            </mesh>
                        </geometry>
                        <material>
                            <ambient>0.1 0.1 0.1 1</ambient>
                            <diffuse>0.1 0.1 0.1 1</diffuse>
                            <specular>0.1 0.1 0.1 1</specular>
                        </material>
                    </visual>
                    <collision name='collision'>
                        <geometry>
                            <mesh>
                                <scale>1 1 1</scale>
                                <uri>meshes/v3/wheel.STL</uri>
                            </mesh>
                        </geometry>
                    </collision>
                </link>

                <joint name='front_right_left_wheel_joint' type='revolute'>
                   <pose relative_to='front_right_left_beam'>0.00748 -0.05 -0.047 0 0 0</pose>
                    <parent>front_right_left_beam</parent>
                    <child>front_right_left_wheel</child>
                    <axis>
                        <xyz expressed_in='__model__'>0 1 0</xyz>
                        <limit>
                            <lower>-1.79769e+308</lower>
                            <upper>1.79769e+308</upper>
                            <velocity>1.79769e+308</velocity>
                            <effort>1.79769e+308</effort>
                        </limit>
                    </axis>
                </joint>

                <!-- ////////////////////////////-->
                <!-- ////////////////////////////-->
                <!-- FRONT RIGHT-RIGHT BEAM -->
                <!-- ////////////////////////////-->
                <!-- ////////////////////////////-->
                <link name='front_right_right_beam'>
                    <pose relative_to='front_right_steering'>0.0075 0.055 -0.31 0 0 0</pose>
                    <inertial>
                        <mass>2</mass>
                        <inertia>
                            <ixx>1.00</ixx>
                            <ixy>0.04</ixy>
                            <ixz>-0.04</ixz>
                            <iyx>-0.05</iyx>
                            <iyy>0.99</iyy>
                            <iyz>-0.11</iyz>
                            <izx>0.04</izx>
                            <izy>0.11</izy>
                            <izz>0.99</izz>
                        </inertia>
                    </inertial>
                    <visual name='visual'>
                        <geometry>
                            <mesh>
                                <scale>1 1 1</scale>
                                <uri>meshes/v3/beam.STL</uri>
                            </mesh>
                        </geometry>
                        <material>
                            <ambient>0.25 0.25 0.25 1</ambient>
                            <diffuse>0.25 0.25 0.25 1</diffuse>
                            <specular>0.25 0.25 0.25 1</specular>
                        </material>
                    </visual>
                    <collision name='collision'>
                        <geometry>
                            <mesh>
                                <scale>1 1 1</scale>
                                <uri>meshes/v3/beam.STL</uri>
                            </mesh>
                        </geometry>
                    </collision>
                </link>

                <joint name='front_right_right_beam_joint' type='revolute'>
                   <pose relative_to='front_right_steering'>-0.09363 0.055 -0.29706 0 0 0</pose>
                    <parent>front_right_steering</parent>
                    <child>front_right_right_beam</child>
                    <axis>
                        <xyz expressed_in='__model__'>0 1 0</xyz>
                        <limit>
                            <lower>-0.9</lower>
                            <upper>0.9</upper>
                            <velocity>10</velocity>
                        </limit>
                        <dynamics>
                            <damping>15</damping>
                            <friction>0.6</friction>
                            <spring_reference>0.06</spring_reference>
                            <spring_stiffness>590</spring_stiffness> <!-- Жесткость пружины -->
                        </dynamics>
                    </axis>
                </joint>

                <!-- ////////////////////////////-->
                <!-- ////////////////////////////-->
                <!-- FRONT RIGHT-RIGHT WHEEL -->
                <!-- ////////////////////////////-->
                <!-- ////////////////////////////-->
                <link name='front_right_right_wheel'>
                    <pose relative_to='front_right_right_beam'>0.00748 0.065 -0.047 0 0 3.1415</pose>
                    <inertial>
                        <mass>18</mass>
                        <inertia>
                            <ixx>0.1</ixx>
                            <ixy>0.00</ixy>
                            <ixz>0.00</ixz>
                            <iyx>0.00</iyx>
                            <iyy>0.1</iyy>
                            <iyz>0.00</iyz>
                            <izx>0.00</izx>
                            <izy>0.00</izy>
                            <izz>0.2</izz>
                        </inertia>
                    </inertial>
                    <visual name='visual'>
                        <geometry>
                            <mesh>
                                <scale>1 1 1</scale>
                                <uri>meshes/v3/wheel.STL</uri>
                            </mesh>
                        </geometry>
                        <material>
                            <ambient>0.1 0.1 0.1 1</ambient>
                            <diffuse>0.1 0.1 0.1 1</diffuse>
                            <specular>0.1 0.1 0.1 1</specular>
                        </material>
                    </visual>
                    <collision name='collision'>
                        <geometry>
                            <mesh>
                                <scale>1 1 1</scale>
                                <uri>meshes/v3/wheel.STL</uri>
                            </mesh>
                        </geometry>
                    </collision>
                </link>

                <joint name='front_right_right_wheel_joint' type='revolute'>
                   <pose relative_to='front_right_right_beam'>0.00748 0.05 -0.047 0 0 0</pose>
                    <parent>front_right_right_beam</parent>
                    <child>front_right_right_wheel</child>
                    <axis>
                        <xyz expressed_in='__model__'>0 1 0</xyz>
                        <limit>
                            <lower>-1.79769e+308</lower>
                            <upper>1.79769e+308</upper>
                            <velocity>1.79769e+308</velocity>
                            <effort>1.79769e+308</effort>
                        </limit>
                    </axis>
                </joint>

                <!-- ////////////////////////////-->
                <!-- ////////////////////////////-->
                <!-- REAR LEFT STEERING -->
                <!-- ////////////////////////////-->
                <!-- ////////////////////////////-->
                <link name='rear_left_steering'>
                    <pose relative_to='base_link'>-0.81000 1.05393 -0.38515 0 0 0</pose>
                    <inertial>
                        <mass>20</mass>
                        <inertia>
                            <ixx>0.01</ixx>
                            <ixy>0.00</ixy>
                            <ixz>0.00</ixz>
                            <iyx>0.00</iyx>
                            <iyy>0.01</iyy>
                            <iyz>0.00</iyz>
                            <izx>0.00</izx>
                            <izy>0.00</izy>
                            <izz>0.01</izz>
                        </inertia>
                    </inertial>
                    <visual name='visual'>
                        <geometry>
                            <mesh>
                                <scale>1 1 1</scale>
                                <uri>meshes/v3/steering.STL</uri>
                            </mesh>
                        </geometry>
                        <material>
                            <ambient>0.25 0.25 0.25 1</ambient>
                            <diffuse>0.25 0.25 0.25 1</diffuse>
                            <specular>0.25 0.25 0.25 1</specular>
                        </material>
                    </visual>
                    <collision name='collision'>
                        <geometry>
                            <mesh>
                                <scale>1 1 1</scale>
                                <uri>meshes/v3/steering.STL</uri>
                            </mesh>
                        </geometry>
                    </collision>
                </link>

                <joint name='rear_left_steering_joint' type='revolute'>
                   <pose relative_to='base_link'>-0.78500 1.0500 -0.38515 0 0 0</pose>
                    <parent>base_link</parent>
                    <child>rear_left_steering</child>
                    <axis>
                        <xyz expressed_in='__model__'>0 0 1</xyz>
                        <limit>
                            <lower>-6.28</lower>
                            <upper>6.28</upper>
                            <velocity>1.79769e+308</velocity>
                            <effort>1.79769e+308</effort>
                        </limit>
                        <dynamics>
                            <damping>20.0</damping>
                            <friction>0.01</friction>
                            <spring_reference>2</spring_reference>
                        </dynamics>
                        <physics>
                            <ode>
                                <cfm>1</cfm>
                                <erp>1</erp>
                                <max_force>1.79769e+308</max_force>
                                <velocity>1.79769e+308</velocity>
                            </ode>
                        </physics>
                    </axis>
                </joint>

                <!-- ////////////////////////////-->
                <!-- ////////////////////////////-->
                <!-- REAR LEFT-LEFT BEAM -->
                <!-- ////////////////////////////-->
                <!-- ////////////////////////////-->
                <link name='rear_left_left_beam'>
                    <pose relative_to='rear_left_steering'>0.0075 0.055 -0.31 0 0 0</pose>
                    <inertial>
                        <mass>2</mass>
                        <inertia>
                            <ixx>1.00</ixx>
                            <ixy>0.04</ixy>
                            <ixz>-0.04</ixz>
                            <iyx>-0.05</iyx>
                            <iyy>0.99</iyy>
                            <iyz>-0.11</iyz>
                            <izx>0.04</izx>
                            <izy>0.11</izy>
                            <izz>0.99</izz>
                        </inertia>
                    </inertial>
                    <visual name='visual'>
                        <geometry>
                            <mesh>
                                <scale>1 1 1</scale>
                                <uri>meshes/v3/beam.STL</uri>
                            </mesh>
                        </geometry>
                        <material>
                            <ambient>0.25 0.25 0.25 1</ambient>
                            <diffuse>0.25 0.25 0.25 1</diffuse>
                            <specular>0.25 0.25 0.25 1</specular>
                        </material>
                    </visual>
                    <collision name='collision'>
                        <geometry>
                            <mesh>
                                <scale>1 1 1</scale>
                                <uri>meshes/v3/beam.STL</uri>
                            </mesh>
                        </geometry>
                    </collision>
                </link>

                <joint name='rear_left_left_beam_joint' type='revolute'>
                   <pose relative_to='rear_left_steering'>-0.09363 0.055 -0.29706 0 0 0</pose>
                    <parent>rear_left_steering</parent>
                    <child>rear_left_left_beam</child>
                    <axis>
                        <xyz expressed_in='__model__'>0 1 0</xyz>
                        <limit>
                            <lower>-0.9</lower>
                            <upper>0.9</upper>
                            <velocity>10</velocity>
                        </limit>
                        <dynamics>
                            <damping>15</damping>
                            <friction>0.6</friction>
                            <spring_reference>0.06</spring_reference>
                            <spring_stiffness>590</spring_stiffness> <!-- Жесткость пружины -->
                        </dynamics>
                    </axis>
                </joint>

                <!-- ////////////////////////////-->
                <!-- ////////////////////////////-->
                <!-- REAR LEFT-LEFT WHEEL -->
                <!-- ////////////////////////////-->
                <!-- ////////////////////////////-->
                <link name='rear_left_left_wheel'>
                    <pose relative_to='rear_left_left_beam'>0.00748 0.065 -0.047 0 0 3.14</pose>
                    <inertial>
                        <mass>18</mass>
                        <inertia>
                            <ixx>0.1</ixx>
                            <ixy>0.00</ixy>
                            <ixz>0.00</ixz>
                            <iyx>0.00</iyx>
                            <iyy>0.1</iyy>
                            <iyz>0.00</iyz>
                            <izx>0.00</izx>
                            <izy>0.00</izy>
                            <izz>0.2</izz>
                        </inertia>
                    </inertial>
                    <visual name='visual'>
                        <geometry>
                            <mesh>
                                <scale>1 1 1</scale>
                                <uri>meshes/v3/wheel.STL</uri>
                            </mesh>
                        </geometry>
                        <material>
                            <ambient>0.1 0.1 0.1 1</ambient>
                            <diffuse>0.1 0.1 0.1 1</diffuse>
                            <specular>0.1 0.1 0.1 1</specular>
                        </material>
                    </visual>
                    <collision name='collision'>
                        <geometry>
                            <mesh>
                                <scale>1 1 1</scale>
                                <uri>meshes/v3/wheel.STL</uri>
                            </mesh>
                        </geometry>
                    </collision>
                </link>

                <joint name='rear_left_left_wheel_joint' type='revolute'>
                   <pose relative_to='rear_left_left_beam'>0.00748 0.05 -0.047 0 0 3.14</pose>
                    <parent>rear_left_left_beam</parent>
                    <child>rear_left_left_wheel</child>
                    <axis>
                        <xyz expressed_in='__model__'>0 1 0</xyz>
                        <limit>
                            <lower>-1.79769e+308</lower>
                            <upper>1.79769e+308</upper>
                            <velocity>1.79769e+308</velocity>
                            <effort>1.79769e+308</effort>
                        </limit>
                    </axis>
                </joint>

                <!-- ////////////////////////////-->
                <!-- ////////////////////////////-->
                <!-- REAR LEFT-RIGHT BEAM -->
                <!-- ////////////////////////////-->
                <!-- ////////////////////////////-->
                <link name='rear_left_right_beam'>
                    <pose relative_to='rear_left_steering'>0.0075 -0.055 -0.31 0 0 0</pose>
                    <inertial>
                        <mass>2</mass>
                        <inertia>
                            <ixx>1.00</ixx>
                            <ixy>0.04</ixy>
                            <ixz>-0.04</ixz>
                            <iyx>-0.05</iyx>
                            <iyy>0.99</iyy>
                            <iyz>-0.11</iyz>
                            <izx>0.04</izx>
                            <izy>0.11</izy>
                            <izz>0.99</izz>
                        </inertia>
                    </inertial>
                    <visual name='visual'>
                        <geometry>
                            <mesh>
                                <scale>1 1 1</scale>
                                <uri>meshes/v3/beam.STL</uri>
                            </mesh>
                        </geometry>
                        <material>
                            <ambient>0.25 0.25 0.25 1</ambient>
                            <diffuse>0.25 0.25 0.25 1</diffuse>
                            <specular>0.25 0.25 0.25 1</specular>
                        </material>
                    </visual>
                    <collision name='collision'>
                        <geometry>
                            <mesh>
                                <scale>1 1 1</scale>
                                <uri>meshes/v3/beam.STL</uri>
                            </mesh>
                        </geometry>
                    </collision>
                </link>

                <joint name='rear_left_right_beam_joint' type='revolute'>
                   <pose relative_to='rear_left_steering'>-0.09363 -0.055 -0.29706 0 0 0</pose>
                    <parent>rear_left_steering</parent>
                    <child>rear_left_right_beam</child>
                    <axis>
                        <xyz expressed_in='__model__'>0 1 0</xyz>
                        <limit>
                            <lower>-0.9</lower>
                            <upper>0.9</upper>
                            <velocity>10</velocity>
                        </limit>
                        <dynamics>
                            <damping>15</damping>
                            <friction>0.6</friction>
                            <spring_reference>0.06</spring_reference>
                            <spring_stiffness>590</spring_stiffness> <!-- Жесткость пружины -->
                        </dynamics>
                    </axis>
                </joint>

                <!-- ////////////////////////////-->
                <!-- ////////////////////////////-->
                <!-- REAR LEFT-RIGHT WHEEL -->
                <!-- ////////////////////////////-->
                <!-- ////////////////////////////-->
                <link name='rear_left_right_wheel'>
                    <pose relative_to='rear_left_right_beam'>0.00748 -0.065 -0.047 0 0 3.1415</pose>
                    <inertial>
                        <mass>18</mass>
                        <inertia>
                            <ixx>0.1</ixx>
                            <ixy>0.00</ixy>
                            <ixz>0.00</ixz>
                            <iyx>0.00</iyx>
                            <iyy>0.1</iyy>
                            <iyz>0.00</iyz>
                            <izx>0.00</izx>
                            <izy>0.00</izy>
                            <izz>0.2</izz>
                        </inertia>
                    </inertial>
                    <visual name='visual'>
                        <geometry>
                            <mesh>
                                <scale>1 1 1</scale>
                                <uri>meshes/v3/wheel.STL</uri>
                            </mesh>
                        </geometry>
                        <material>
                            <ambient>0.1 0.1 0.1 1</ambient>
                            <diffuse>0.1 0.1 0.1 1</diffuse>
                            <specular>0.1 0.1 0.1 1</specular>
                        </material>
                    </visual>
                    <collision name='collision'>
                        <geometry>
                            <mesh>
                                <scale>1 1 1</scale>
                                <uri>meshes/v3/wheel.STL</uri>
                            </mesh>
                        </geometry>
                    </collision>
                </link>

                <joint name='rear_left_right_wheel_joint' type='revolute'>
                   <pose relative_to='rear_left_right_beam'>0.00748 -0.05 -0.047 0 0 0</pose>
                    <parent>rear_left_right_beam</parent>
                    <child>rear_left_right_wheel</child>
                    <axis>
                        <xyz expressed_in='__model__'>0 1 0</xyz>
                        <limit>
                            <lower>-1.79769e+308</lower>
                            <upper>1.79769e+308</upper>
                            <velocity>1.79769e+308</velocity>
                            <effort>1.79769e+308</effort>
                        </limit>
                    </axis>
                </joint>

                <!-- ////////////////////////////-->
                <!-- ////////////////////////////-->
                <!-- REAR RIGHT STEERING -->
                <!-- ////////////////////////////-->
                <!-- ////////////////////////////-->
                <link name='rear_right_steering'>
                    <pose relative_to='base_link'>-0.81000 -1.05393 -0.38515 0 0 0</pose>
                    <inertial>
                        <mass>20</mass>
                        <inertia>
                            <ixx>0.01</ixx>
                            <ixy>0.00</ixy>
                            <ixz>0.00</ixz>
                            <iyx>0.00</iyx>
                            <iyy>0.01</iyy>
                            <iyz>0.00</iyz>
                            <izx>0.00</izx>
                            <izy>0.00</izy>
                            <izz>0.01</izz>
                        </inertia>
                    </inertial>
                    <visual name='visual'>
                        <geometry>
                            <mesh>
                                <scale>1 1 1</scale>
                                <uri>meshes/v3/steering.STL</uri>
                            </mesh>
                        </geometry>
                        <material>
                            <ambient>0.25 0.25 0.25 1</ambient>
                            <diffuse>0.25 0.25 0.25 1</diffuse>
                            <specular>0.25 0.25 0.25 1</specular>
                        </material>
                    </visual>
                    <collision name='collision'>
                        <geometry>
                            <mesh>
                                <scale>1 1 1</scale>
                                <uri>meshes/v3/steering.STL</uri>
                            </mesh>
                        </geometry>
                    </collision>
                </link>

                <joint name='rear_right_steering_joint' type='revolute'>
                   <pose relative_to='base_link'>-0.78500 -1.0500 -0.38515 0 0 0</pose>
                    <parent>base_link</parent>
                    <child>rear_right_steering</child>
                    <axis>
                        <xyz expressed_in='__model__'>0 0 1</xyz>
                        <limit>
                            <lower>-6.28</lower>
                            <upper>6.28</upper>
                            <velocity>1.79769e+308</velocity>
                            <effort>1.79769e+308</effort>
                        </limit>
                        <dynamics>
                            <damping>20.0</damping>
                            <friction>0.01</friction>
                            <spring_reference>2</spring_reference>
                        </dynamics>
                        <physics>
                            <ode>
                                <cfm>1</cfm>
                                <erp>1</erp>
                                <max_force>1.79769e+308</max_force>
                                <velocity>1.79769e+308</velocity>
                            </ode>
                        </physics>
                    </axis>
                </joint>

                <!-- ////////////////////////////-->
                <!-- ////////////////////////////-->
                <!-- REAR RIGHT-LEFT BEAM -->
                <!-- ////////////////////////////-->
                <!-- ////////////////////////////-->
                <link name='rear_right_left_beam'>
                    <pose relative_to='rear_right_steering'>0.0075 0.055 -0.31 0 0 0</pose>
                    <inertial>
                        <mass>2</mass>
                        <inertia>
                            <ixx>1.00</ixx>
                            <ixy>0.04</ixy>
                            <ixz>-0.04</ixz>
                            <iyx>-0.05</iyx>
                            <iyy>0.99</iyy>
                            <iyz>-0.11</iyz>
                            <izx>0.04</izx>
                            <izy>0.11</izy>
                            <izz>0.99</izz>
                        </inertia>
                    </inertial>
                    <visual name='visual'>
                        <geometry>
                            <mesh>
                                <scale>1 1 1</scale>
                                <uri>meshes/v3/beam.STL</uri>
                            </mesh>
                        </geometry>
                        <material>
                            <ambient>0.25 0.25 0.25 1</ambient>
                            <diffuse>0.25 0.25 0.25 1</diffuse>
                            <specular>0.25 0.25 0.25 1</specular>
                        </material>
                    </visual>
                    <collision name='collision'>
                        <geometry>
                            <mesh>
                                <scale>1 1 1</scale>
                                <uri>meshes/v3/beam.STL</uri>
                            </mesh>
                        </geometry>
                    </collision>
                </link>

                <joint name='rear_right_left_beam_joint' type='revolute'>
                   <pose relative_to='rear_right_steering'>-0.09363 0.055 -0.29706 0 0 0</pose>
                    <parent>rear_right_steering</parent>
                    <child>rear_right_left_beam</child>
                    <axis>
                        <xyz expressed_in='__model__'>0 1 0</xyz>
                        <limit>
                            <lower>-0.9</lower>
                            <upper>0.9</upper>
                            <velocity>10</velocity>
                        </limit>
                        <dynamics>
                            <damping>15</damping>
                            <friction>0.6</friction>
                            <spring_reference>0.06</spring_reference>
                            <spring_stiffness>590</spring_stiffness> <!-- Жесткость пружины -->
                        </dynamics>
                    </axis>
                </joint>

                <!-- ////////////////////////////-->
                <!-- ////////////////////////////-->
                <!-- REAR RIGHT-LEFT WHEEL -->
                <!-- ////////////////////////////-->
                <!-- ////////////////////////////-->
                <link name='rear_right_left_wheel'>
                    <pose relative_to='rear_right_left_beam'>0.00748 0.065 -0.047 0 0 0</pose>
                    <inertial>
                        <mass>18</mass>
                        <inertia>
                            <ixx>0.1</ixx>
                            <ixy>0.00</ixy>
                            <ixz>0.00</ixz>
                            <iyx>0.00</iyx>
                            <iyy>0.1</iyy>
                            <iyz>0.00</iyz>
                            <izx>0.00</izx>
                            <izy>0.00</izy>
                            <izz>0.2</izz>
                        </inertia>
                    </inertial>
                    <visual name='visual'>
                        <geometry>
                            <mesh>
                                <scale>1 1 1</scale>
                                <uri>meshes/v3/wheel.STL</uri>
                            </mesh>
                        </geometry>
                        <material>
                            <ambient>0.1 0.1 0.1 1</ambient>
                            <diffuse>0.1 0.1 0.1 1</diffuse>
                            <specular>0.1 0.1 0.1 1</specular>
                        </material>
                    </visual>
                    <collision name='collision'>
                        <geometry>
                            <mesh>
                                <scale>1 1 1</scale>
                                <uri>meshes/v3/wheel.STL</uri>
                            </mesh>
                        </geometry>
                    </collision>
                </link>

                <joint name='rear_right_left_wheel_joint' type='revolute'>
                   <pose relative_to='rear_right_left_beam'>0.00748 -0.05 -0.047 0 0 0</pose>
                    <parent>rear_right_left_beam</parent>
                    <child>rear_right_left_wheel</child>
                    <axis>
                        <xyz expressed_in='__model__'>0 1 0</xyz>
                        <limit>
                            <lower>-1.79769e+308</lower>
                            <upper>1.79769e+308</upper>
                            <velocity>1.79769e+308</velocity>
                            <effort>1.79769e+308</effort>
                        </limit>
                    </axis>
                </joint>

                <!-- ////////////////////////////-->
                <!-- ////////////////////////////-->
                <!-- REAR RIGHT-RIGHT BEAM -->
                <!-- ////////////////////////////-->
                <!-- ////////////////////////////-->
                <link name='rear_right_right_beam'>
                    <pose relative_to='rear_right_steering'>0.0075 -0.055 -0.31 0 0 0</pose>
                    <inertial>
                        <mass>2</mass>
                        <inertia>
                            <ixx>1.00</ixx>
                            <ixy>0.04</ixy>
                            <ixz>-0.04</ixz>
                            <iyx>-0.05</iyx>
                            <iyy>0.99</iyy>
                            <iyz>-0.11</iyz>
                            <izx>0.04</izx>
                            <izy>0.11</izy>
                            <izz>0.99</izz>
                        </inertia>
                    </inertial>
                    <visual name='visual'>
                        <geometry>
                            <mesh>
                                <scale>1 1 1</scale>
                                <uri>meshes/v3/beam.STL</uri>
                            </mesh>
                        </geometry>
                        <material>
                            <ambient>0.25 0.25 0.25 1</ambient>
                            <diffuse>0.25 0.25 0.25 1</diffuse>
                            <specular>0.25 0.25 0.25 1</specular>
                        </material>
                    </visual>
                    <collision name='collision'>
                        <geometry>
                            <mesh>
                                <scale>1 1 1</scale>
                                <uri>meshes/v3/beam.STL</uri>
                            </mesh>
                        </geometry>
                    </collision>
                </link>

                <joint name='rear_right_right_beam_joint' type='revolute'>
                   <pose relative_to='rear_right_steering'>-0.09363 -0.055 -0.29706 0 0 0</pose>
                    <parent>rear_right_steering</parent>
                    <child>rear_right_right_beam</child>
                    <axis>
                        <xyz expressed_in='__model__'>0 1 0</xyz>
                        <limit>
                            <lower>-0.9</lower>
                            <upper>0.9</upper>
                            <velocity>10</velocity>
                        </limit>
                        <dynamics>
                            <damping>15</damping>
                            <friction>0.6</friction>
                            <spring_reference>0.06</spring_reference>
                            <spring_stiffness>590</spring_stiffness> <!-- Жесткость пружины -->
                        </dynamics>
                    </axis>
                </joint>

                <!-- ////////////////////////////-->
                <!-- ////////////////////////////-->
                <!-- REAR RIGHT-RIGHT WHEEL -->
                <!-- ////////////////////////////-->
                <!-- ////////////////////////////-->
                <link name='rear_right_right_wheel'>
                    <pose relative_to='rear_right_right_beam'>0.00748 -0.065 -0.047 0 0 3.1415</pose>
                    <inertial>
                        <mass>18</mass>
                        <inertia>
                            <ixx>0.1</ixx>
                            <ixy>0.00</ixy>
                            <ixz>0.00</ixz>
                            <iyx>0.00</iyx>
                            <iyy>0.1</iyy>
                            <iyz>0.00</iyz>
                            <izx>0.00</izx>
                            <izy>0.00</izy>
                            <izz>0.2</izz>
                        </inertia>
                    </inertial>
                    <visual name='visual'>
                        <geometry>
                            <mesh>
                                <scale>1 1 1</scale>
                                <uri>meshes/v3/wheel.STL</uri>
                            </mesh>
                        </geometry>
                        <material>
                            <ambient>0.1 0.1 0.1 1</ambient>
                            <diffuse>0.1 0.1 0.1 1</diffuse>
                            <specular>0.1 0.1 0.1 1</specular>
                        </material>
                    </visual>
                    <collision name='collision'>
                        <geometry>
                            <mesh>
                                <scale>1 1 1</scale>
                                <uri>meshes/v3/wheel.STL</uri>
                            </mesh>
                        </geometry>
                    </collision>
                </link>

                <joint name='rear_right_right_wheel_joint' type='revolute'>
                   <pose relative_to='rear_right_right_beam'>0.00748 -0.05 -0.047 0 0 0</pose>
                    <parent>rear_right_right_beam</parent>
                    <child>rear_right_right_wheel</child>
                    <axis>
                        <xyz expressed_in='__model__'>0 1 0</xyz>
                        <limit>
                            <lower>-1.79769e+308</lower>
                            <upper>1.79769e+308</upper>
                            <velocity>1.79769e+308</velocity>
                            <effort>1.79769e+308</effort>
                        </limit>
                    </axis>
                </joint>

                <!-- ////////////////////////////-->
                <!-- ////////////////////////////-->
                <!-- WHEEL PLUGINS -->
                <!-- ////////////////////////////-->
                <!-- ////////////////////////////-->
               <plugin filename="gz-sim-joint-controller-system" name="gz::sim::systems::JointController">
                   <joint_name>front_left_left_wheel_joint</joint_name>
                   <topic>/front_left_left_wheel</topic>
                   <initial_velocity>0.0</initial_velocity>
                   <cmd_max>30</cmd_max>
                   <cmd_min>-30</cmd_min>
               </plugin>
                <plugin filename="gz-sim-joint-controller-system" name="gz::sim::systems::JointController">
                   <joint_name>front_left_right_wheel_joint</joint_name>
                   <topic>/front_left_right_wheel</topic>
                   <initial_velocity>0.0</initial_velocity>
                   <cmd_max>30</cmd_max>
                   <cmd_min>-30</cmd_min>
               </plugin>
                <plugin filename="gz-sim-joint-controller-system" name="gz::sim::systems::JointController">
                   <joint_name>front_right_left_wheel_joint</joint_name>
                   <topic>/front_right_left_wheel</topic>
                   <initial_velocity>0.0</initial_velocity>
                   <cmd_max>30</cmd_max>
                   <cmd_min>-30</cmd_min>
               </plugin>
               <plugin filename="gz-sim-joint-controller-system" name="gz::sim::systems::JointController">
                   <joint_name>front_right_right_wheel_joint</joint_name>
                   <topic>/front_right_right_wheel</topic>
                   <initial_velocity>0.0</initial_velocity>
                   <cmd_max>30</cmd_max>
                   <cmd_min>-30</cmd_min>
               </plugin>
               <plugin filename="gz-sim-joint-controller-system" name="gz::sim::systems::JointController">
                   <joint_name>rear_left_left_wheel_joint</joint_name>
                   <topic>/rear_left_left_wheel</topic>
                   <initial_velocity>0.0</initial_velocity>
                   <cmd_max>30</cmd_max>
                   <cmd_min>-30</cmd_min>
               </plugin>
                <plugin filename="gz-sim-joint-controller-system" name="gz::sim::systems::JointController">
                   <joint_name>rear_left_right_wheel_joint</joint_name>
                   <topic>/rear_left_right_wheel</topic>
                   <initial_velocity>0.0</initial_velocity>
                   <cmd_max>30</cmd_max>
                   <cmd_min>-30</cmd_min>
               </plugin>
               <plugin filename="gz-sim-joint-controller-system" name="gz::sim::systems::JointController">
                   <joint_name>rear_right_left_wheel_joint</joint_name>
                   <topic>/rear_right_left_wheel</topic>
                   <initial_velocity>0.0</initial_velocity>
                   <cmd_max>30</cmd_max>
                   <cmd_min>-30</cmd_min>
               </plugin>
                <plugin filename="gz-sim-joint-controller-system" name="gz::sim::systems::JointController">
                   <joint_name>rear_right_right_wheel_joint</joint_name>
                   <topic>/rear_right_right_wheel</topic>
                   <initial_velocity>0.0</initial_velocity>
                   <cmd_max>30</cmd_max>
                   <cmd_min>-30</cmd_min>
               </plugin>

               <!-- ////////////////////////////-->
               <!-- ////////////////////////////-->
               <!-- STEERING PLUGINS -->
               <!-- ////////////////////////////-->
               <!-- ////////////////////////////-->
               <plugin filename="gz-sim-joint-position-controller-system" name="gz::sim::systems::JointPositionController">
                    <joint_name>front_left_steering_joint</joint_name>
                    <topic>/front_left_steering</topic>
                    <p_gain>5000</p_gain>
                    <i_gain>0.0</i_gain>
                    <d_gain>100.0</d_gain>
                    <i_max>0</i_max>
                    <i_min>-0</i_min>
                    <cmd_max>100</cmd_max>
                    <cmd_min>-100</cmd_min>

               </plugin>
               <plugin filename="gz-sim-joint-position-controller-system" name="gz::sim::systems::JointPositionController">
                    <joint_name>front_right_steering_joint</joint_name>
                    <topic>/front_right_steering</topic>
                    <p_gain>5000</p_gain>
                    <i_gain>0.0</i_gain>
                    <d_gain>100.0</d_gain>
                    <i_max>0</i_max>
                    <i_min>-0</i_min>
                    <cmd_max>100</cmd_max>
                    <cmd_min>-100</cmd_min>
               </plugin>
               <plugin filename="gz-sim-joint-position-controller-system" name="gz::sim::systems::JointPositionController">
                    <joint_name>rear_left_steering_joint</joint_name>
                    <topic>/rear_left_steering</topic>
                    <p_gain>5000</p_gain>
                    <i_gain>0.0</i_gain>
                    <d_gain>100.0</d_gain>
                    <i_max>0</i_max>
                    <i_min>-0</i_min>
                    <cmd_max>100</cmd_max>
                    <cmd_min>-100</cmd_min>
               </plugin>
               <plugin filename="gz-sim-joint-position-controller-system" name="gz::sim::systems::JointPositionController">
                    <joint_name>rear_right_steering_joint</joint_name>
                    <topic>/rear_right_steering</topic>
                    <p_gain>5000</p_gain>
                    <i_gain>0.0</i_gain>
                    <d_gain>100.0</d_gain>
                    <i_max>0</i_max>
                    <i_min>-0</i_min>
                    <cmd_max>100</cmd_max>
                    <cmd_min>-100</cmd_min>
               </plugin>

               <!-- ////////////////////////////-->
               <!-- ////////////////////////////-->
               <!-- JOINT STATE PUBLISHER PLUGIN -->
               <!-- ////////////////////////////-->
               <!-- ////////////////////////////-->
               <plugin filename="gz-sim-joint-state-publisher-system" name="gz::sim::systems::JointStatePublisher">
                   <joint_name>base_footprint_joint</joint_name>
                   <joint_name>front_left_steering_joint</joint_name>
                   <joint_name>front_right_steering_joint</joint_name>
                   <joint_name>rear_left_steering_joint</joint_name>
                   <joint_name>rear_right_steering_joint</joint_name>

                   <joint_name>front_left_left_wheel_joint</joint_name>
                   <joint_name>front_left_right_wheel_joint</joint_name>
                   <joint_name>front_right_left_wheel_joint</joint_name>
                   <joint_name>front_right_right_wheel_joint</joint_name>
                   <joint_name>rear_left_left_wheel_joint</joint_name>
                   <joint_name>rear_left_right_wheel_joint</joint_name>
                   <joint_name>rear_right_left_wheel_joint</joint_name>
                   <joint_name>rear_right_right_wheel_joint</joint_name>
<!--                   <joint_name>rgbd_joint</joint_name>-->
                   <topic>/joint_states</topic>
               </plugin>
                <!-- ////////////////////////////-->
                <!-- ////////////////////////////-->
                <!-- ODOMETRY PLUGIN -->
                <!-- ////////////////////////////-->
                <!-- ////////////////////////////-->
                <plugin filename="gz-sim-odometry-publisher-system"
                    name="gz::sim::systems::OdometryPublisher">
                    <odom_frame>odom</odom_frame>
                    <robot_base_frame>base_link</robot_base_frame>
                    <odom_publish_frequency>30</odom_publish_frequency>
                    <odom_topic>/odometry</odom_topic>
                    <odom_covariance_topic>/odometry_with_covariance</odom_covariance_topic>
                    <tf_topic>/tf</tf_topic>
                    <dimensions>2</dimensions>
                </plugin>
                <!-- ////////////////////////////-->
               <!-- ////////////////////////////-->
               <!-- SENSORS PLUGIN -->
               <!-- ////////////////////////////-->
               <!-- ////////////////////////////-->
                <plugin filename="gz-sim-imu-system"
                        name="gz::sim::systems::Imu">
                </plugin>
                <plugin filename="gz-sim-navsat-system"
                        name="gz::sim::systems::NavSat">
                </plugin>
               <plugin
                  filename="gz-sim-sensors-system"
                  name="gz::sim::systems::Sensors">
                  <render_engine>ogre2</render_engine>
               </plugin>
            </model>


        </world>
    </sdf>